<?xml version="1.0" encoding="utf-8"?>
<!-- This URDF was automatically created by SolidWorks to URDF Exporter! Originally created by Stephen Brawner (brawner@gmail.com) 
     Commit Version: 1.6.0-4-g7f85cfe  Build Version: 1.6.7995.38578
     For more information, please see http://wiki.ros.org/sw_urdf_exporter -->
<robot
  name="Fridge-bot">
  <link name="world" />

  <joint name="world_to_base_link=" type="fixed">
    <parent link="world"/>
    <child link="base_link"/>
    <origin
        xyz="0 0 1"
        rpy="0 0 0" />
  </joint>
  <link
    name="base_link">
    <inertial>
      <origin
        xyz="0.065744341564924 0.045216580467112 0.0494910882181169"
        rpy="0 3.14 0" />
      <mass
        value="0.207046380810351" />
      <inertia
        ixx="0.000296100160478881"
        ixy="-2.96509727065676E-09"
        ixz="4.1481005406492E-07"
        iyy="0.000510587496763238"
        iyz="-2.58760118911616E-11"
        izz="0.000248571256331813" />
    </inertial>
    <visual>
      <origin
        xyz="0 0 0"
        rpy="0 3.14 0" />
      <geometry>
        <mesh
          filename="package://fridge_bot/src/meshes/base_link.STL" />
      </geometry>
      <material
        name="">
        <color
          rgba="0.792156862745098 0.819607843137255 0.933333333333333 1" />
      </material>
    </visual>
    <collision>
      <origin
        xyz="0 0 0"
        rpy="0 0 0" />
      <geometry>
        <mesh
          filename="package://fridge_bot/src/meshes/base_link.STL" />
      </geometry>
    </collision>
  </link>
  <link
    name="Turning_link">
    <inertial>
      <origin
        xyz="-0.0267697026327348 0.00488148698796461 0.0222183347728628"
        rpy="0 0 0" />
      <mass
        value="0.19237125582213" />
      <inertia
        ixx="0.000135901413995399"
        ixy="-1.33820761853295E-06"
        ixz="2.84315818360693E-06"
        iyy="0.000156555561267971"
        iyz="2.6996128156746E-06"
        izz="0.000197919660234674" />
    </inertial>
    <visual>
      <origin
        xyz="0 0 0"
        rpy="0 0 0" />
      <geometry>
        <mesh
          filename="package://fridge_bot/src/meshes/Turning_link.STL" />
      </geometry>
      <material
        name="">
        <color
          rgba="0.792156862745098 0.819607843137255 0.933333333333333 1" />
      </material>
    </visual>
    <collision>
      <origin
        xyz="0 0 0"
        rpy="0 0 0" />
      <geometry>
        <mesh
          filename="package://fridge_bot/src/meshes/Turning_link.STL" />
      </geometry>
    </collision>
  </link>
  <joint
    name="J1"
    type="revolute">
    <origin
      xyz="0.06605 0.032302 0.014542"
      rpy="1.5708 -0.0040186 0" />
    <parent
      link="base_link" />
    <child
      link="Turning_link" />
    <axis
      xyz="0 0 -1" />
    <limit
      lower="0"
      upper="6.28"
      effort="0"
      velocity="0" />
  </joint>
  <link
    name="Lower_backlink">
    <inertial>
      <origin
        xyz="0.0414635494994407 6.93889390390723E-18 0.00499999999999996"
        rpy="0 0 0" />
      <mass
        value="0.0193744467859455" />
      <inertia
        ixx="8.00416835228504E-07"
        ixy="-3.3881317890172E-21"
        ixz="4.52614911442815E-21"
        iyy="1.54913654040111E-05"
        iyz="1.88996064051875E-22"
        izz="1.59688747928072E-05" />
    </inertial>
    <visual>
      <origin
        xyz="0 0 0"
        rpy="0 0 0" />
      <geometry>
        <mesh
          filename="package://fridge_bot/src/meshes/Lower_backlink.STL" />
      </geometry>
      <material
        name="">
        <color
          rgba="0.792156862745098 0.819607843137255 0.933333333333333 1" />
      </material>
    </visual>
    <collision>
      <origin
        xyz="0 0 0"
        rpy="0 0 0" />
      <geometry>
        <mesh
          filename="package://fridge_bot/src/meshes/Lower_backlink.STL" />
      </geometry>
    </collision>
  </link>
  <joint
    name="J2"
    type="continuous">
    <origin
      xyz="-0.0225 -0.022855 0.065355"
      rpy="-1.5708 -1.0628 1.5708" />
    <parent
      link="Turning_link" />
    <child
      link="Lower_backlink" />
    <axis
      xyz="0 0 -1" />
  </joint>
  <link
    name="Link1">
    <inertial>
      <origin
        xyz="-2.35922392732846E-16 -0.0999111796922045 -0.00999999999999946"
        rpy="0 0 0" />
      <mass
        value="0.0855737940510451" />
      <inertia
        ixx="0.000328606447348668"
        ixy="-8.20986684126231E-19"
        ixz="-4.72153637505962E-22"
        iyy="3.53584860057504E-06"
        iyz="-2.15784962745792E-16"
        izz="0.000330716066048393" />
    </inertial>
    <visual>
      <origin
        xyz="0 0 0"
        rpy="0 0 0" />
      <geometry>
        <mesh
          filename="package://fridge_bot/src/meshes/Link1.STL" />
      </geometry>
      <material
        name="">
        <color
          rgba="0.792156862745098 0.819607843137255 0.933333333333333 1" />
      </material>
    </visual>
    <collision>
      <origin
        xyz="0 0 0"
        rpy="0 0 0" />
      <geometry>
        <mesh
          filename="package://fridge_bot/src/meshes/Link1.STL" />
      </geometry>
    </collision>
  </link>
  <joint
    name="J3"
    type="revolute">
    <origin
      xyz="-0.0275 0.0125 0.03"
      rpy="-1.5708 0.49038 1.5708" />
    <parent
      link="Turning_link" />
    <child
      link="Link1" />
    <axis
      xyz="0 0 -1" />
    <limit
      lower="0"
      upper="6.28"
      effort="0"
      velocity="0" />
  </joint>
  <link
    name="Triangle">
    <inertial>
      <origin
        xyz="0.0128671162531902 0.0149668569116932 0.005"
        rpy="0 0 0" />
      <mass
        value="0.0191246861766036" />
      <inertia
        ixx="5.62289539865078E-06"
        ixy="2.73395813990835E-06"
        ixz="-5.92896539083225E-22"
        iyy="4.65318566936927E-06"
        iyz="5.42998781656638E-22"
        izz="9.95733629840999E-06" />
    </inertial>
    <visual>
      <origin
        xyz="0 0 0"
        rpy="0 0 0" />
      <geometry>
        <mesh
          filename="package://fridge_bot/src/meshes/Triangle.STL" />
      </geometry>
      <material
        name="">
        <color
          rgba="0.792156862745098 0.819607843137255 0.933333333333333 1" />
      </material>
    </visual>
    <collision>
      <origin
        xyz="0 0 0"
        rpy="0 0 0" />
      <geometry>
        <mesh
          filename="package://fridge_bot/src/meshes/Triangle.STL" />
      </geometry>
    </collision>
  </link>
  <joint
    name="J4"
    type="continuous">
    <origin
      xyz="0 -0.2 -0.015"
      rpy="0 0 3.0193" />
    <parent
      link="Link1" />
    <child
      link="Triangle" />
    <axis
      xyz="0 0 1" />
  </joint>
  <link
    name="Upper_backlink">
    <inertial>
      <origin
        xyz="0.0414635494994406 5.55111512312578E-16 0.00499999999999998"
        rpy="0 0 0" />
      <mass
        value="0.0193744467859455" />
      <inertia
        ixx="8.00416835228507E-07"
        ixy="1.07467305182889E-20"
        ixz="9.79827535050522E-22"
        iyy="1.54913654040111E-05"
        iyz="-2.98745253902473E-22"
        izz="1.59688747928072E-05" />
    </inertial>
    <visual>
      <origin
        xyz="0 0 0"
        rpy="0 0 0" />
      <geometry>
        <mesh
          filename="package://fridge_bot/src/meshes/Upper_backlink.STL" />
      </geometry>
      <material
        name="">
        <color
          rgba="0.792156862745098 0.819607843137255 0.933333333333333 1" />
      </material>
    </visual>
    <collision>
      <origin
        xyz="0 0 0"
        rpy="0 0 0" />
      <geometry>
        <mesh
          filename="package://fridge_bot/src/meshes/Upper_backlink.STL" />
      </geometry>
    </collision>
  </link>
  <joint
    name="J5"
    type="continuous">
    <origin
      xyz="0.045 0 0.02"
      rpy="3.1416 0 -1.4308" />
    <parent
      link="Triangle" />
    <child
      link="Upper_backlink" />
    <axis
      xyz="0 0 -1" />
  </joint>
  <link
    name="Upper_frontLink">
    <inertial>
      <origin
        xyz="0.0463904561233811 -6.45872244575685E-14 7.9956874454723E-14"
        rpy="0 0 0" />
      <mass
        value="0.0214124502395769" />
      <inertia
        ixx="8.8417413172566E-07"
        ixy="-2.26226618343863E-17"
        ixz="3.03411185861136E-17"
        iyy="2.08029877158262E-05"
        iyz="-6.48649465622115E-23"
        izz="2.13302876768923E-05" />
    </inertial>
    <visual>
      <origin
        xyz="0 0 0"
        rpy="0 0 0" />
      <geometry>
        <mesh
          filename="package://fridge_bot/src/meshes/Upper_frontLink.STL" />
      </geometry>
      <material
        name="">
        <color
          rgba="0.792156862745098 0.819607843137255 0.933333333333333 1" />
      </material>
    </visual>
    <collision>
      <origin
        xyz="0 0 0"
        rpy="0 0 0" />
      <geometry>
        <mesh
          filename="package://fridge_bot/src/meshes/Upper_frontLink.STL" />
      </geometry>
    </collision>
  </link>
  <joint
    name="J6"
    type="continuous">
    <origin
      xyz="0 0.05 -0.005"
      rpy="3.1416 0 -2.48" />
    <parent
      link="Triangle" />
    <child
      link="Upper_frontLink" />
    <axis
      xyz="0 0 -1" />
  </joint>
  <link
    name="Link2">
    <inertial>
      <origin
        xyz="2.77555756156289E-17 -0.0863342210093204 0.0247054628952012"
        rpy="0 0 0" />
      <mass
        value="0.0953394410565643" />
      <inertia
        ixx="0.000470411650298866"
        ixy="5.4315987742682E-19"
        ixz="1.51753137276197E-21"
        iyy="3.95014826174653E-06"
        iyz="-3.09405752680569E-16"
        izz="0.000472772807876337" />
    </inertial>
    <visual>
      <origin
        xyz="0 0 0"
        rpy="0 0 0" />
      <geometry>
        <mesh
          filename="package://fridge_bot/src/meshes/Link2.STL" />
      </geometry>
      <material
        name="">
        <color
          rgba="0.792156862745098 0.819607843137255 0.933333333333333 1" />
      </material>
    </visual>
    <collision>
      <origin
        xyz="0 0 0"
        rpy="0 0 0" />
      <geometry>
        <mesh
          filename="package://fridge_bot/src/meshes/Link2.STL" />
      </geometry>
    </collision>
  </link>
  <joint
    name="J7"
    type="revolute">
    <origin
      xyz="0 -0.2 0.01"
      rpy="3.1416 0 -1.0177" />
    <parent
      link="Link1" />
    <child
      link="Link2" />
    <axis
      xyz="0 0 -1" />
    <limit
      lower="0"
      upper="6.28"
      effort="0"
      velocity="0" />
  </joint>
  <link
    name="Back_gripper">
    <inertial>
      <origin
        xyz="-0.0250028133017936 0.0239301160957177 0.00141734074678103"
        rpy="0 0 0" />
      <mass
        value="1.53802958602338" />
      <inertia
        ixx="0.000909413538569685"
        ixy="8.26533997142431E-05"
        ixz="-2.76680034671548E-05"
        iyy="0.000912566548096114"
        iyz="-4.94357740447193E-05"
        izz="0.00115501581802408" />
    </inertial>
    <visual>
      <origin
        xyz="0 0 0"
        rpy="0 0 0" />
      <geometry>
        <mesh
          filename="package://fridge_bot/src/meshes/Back_gripper.STL" />
      </geometry>
      <material
        name="">
        <color
          rgba="0.537254901960784 0.349019607843137 0.337254901960784 1" />
      </material>
    </visual>
    <collision>
      <origin
        xyz="0 0 0"
        rpy="0 0 0" />
      <geometry>
        <mesh
          filename="package://fridge_bot/src/meshes/Back_gripper.STL" />
      </geometry>
    </collision>
  </link>
  <joint
    name="J8"
    type="continuous">
    <origin
      xyz="0 -0.2 0.022327"
      rpy="3.1416 0 2.5048" />
    <parent
      link="Link2" />
    <child
      link="Back_gripper" />
    <axis
      xyz="0 0 1" />
  </joint>
  <link
    name="front_halfgripper">
    <inertial>
      <origin
        xyz="-0.000216464748702024 0.0283235783013315 0.0142900639859031"
        rpy="0 0 0" />
      <mass
        value="0.558596679661737" />
      <inertia
        ixx="0.000309404274315498"
        ixy="-3.91459968046766E-05"
        ixz="3.65468624887361E-06"
        iyy="0.000256279098899188"
        iyz="8.07700601429671E-06"
        izz="0.00046459335100017" />
    </inertial>
    <visual>
      <origin
        xyz="0 0 0"
        rpy="0 0 0" />
      <geometry>
        <mesh
          filename="package://fridge_bot/src/meshes/front_halfgripper.STL" />
      </geometry>
      <material
        name="">
        <color
          rgba="0.537254901960784 0.349019607843137 0.337254901960784 1" />
      </material>
    </visual>
    <collision>
      <origin
        xyz="0 0 0"
        rpy="0 0 0" />
      <geometry>
        <mesh
          filename="package://fridge_bot/src/meshes/front_halfgripper.STL" />
      </geometry>
    </collision>
  </link>
  <joint
    name="J9"
    type="revolute">
    <origin
      xyz="-0.054 0.0035 -8.2845E-05"
      rpy="1.5708 1.5515 -3.1416" />
    <parent
      link="Back_gripper" />
    <child
      link="front_halfgripper" />
    <axis
      xyz="0 0.00012782 1" />
    <limit
      lower="0"
      upper="6.28"
      effort="0"
      velocity="0" />
  </joint>
  <link
    name="gripper">
    <inertial>
      <origin
        xyz="0.0309607104904638 -4.59355418679364E-05 0.017144407490665"
        rpy="0 0 0" />
      <mass
        value="0.0686737389522782" />
      <inertia
        ixx="6.40644623542164E-06"
        ixy="-1.58915253493507E-10"
        ixz="3.10523081266725E-06"
        iyy="2.87092893917181E-05"
        iyz="3.68993537350604E-11"
        izz="2.25895985442529E-05" />
    </inertial>
    <visual>
      <origin
        xyz="0 0 0"
        rpy="0 0 0" />
      <geometry>
        <mesh
          filename="package://fridge_bot/src/meshes/gripper.STL" />
      </geometry>
      <material
        name="">
        <color
          rgba="0.537254901960784 0.349019607843137 0.337254901960784 1" />
      </material>
    </visual>
    <collision>
      <origin
        xyz="0 0 0"
        rpy="0 0 0" />
      <geometry>
        <mesh
          filename="package://fridge_bot/src/gripper.STL" />
      </geometry>
    </collision>
  </link>
  <joint
    name="J10"
    type="revolute">
    <origin
      xyz="0.012523 0.027447 -0.004"
      rpy="0 0 1.7772" />
    <parent
      link="front_halfgripper" />
    <child
      link="gripper" />
    <axis
      xyz="-0.0001246 2.8609E-05 -1" />
    <limit
      lower="0"
      upper="6.28"
      effort="0"
      velocity="0" />
  </joint>
  <link
    name="Lower_frontlink">
    <inertial>
      <origin
        xyz="0.0463904561233882 -6.10067552031524E-14 7.99707522425308E-14"
        rpy="0 0 0" />
      <mass
        value="0.0214124502395769" />
      <inertia
        ixx="8.84174131725665E-07"
        ixy="-2.26162561477226E-17"
        ixz="3.03388488913352E-17"
        iyy="2.08029877158262E-05"
        iyz="8.13942229557454E-23"
        izz="2.13302876768922E-05" />
    </inertial>
    <visual>
      <origin
        xyz="0 0 0"
        rpy="0 0 0" />
      <geometry>
        <mesh
          filename="package://fridge_bot/src/meshes/Lower_frontlink.STL" />
      </geometry>
      <material
        name="">
        <color
          rgba="0.792156862745098 0.819607843137255 0.933333333333333 1" />
      </material>
    </visual>
    <collision>
      <origin
        xyz="0 0 0"
        rpy="0 0 0" />
      <geometry>
        <mesh
          filename="package://fridge_bot/src/meshes/Lower_frontlink.STL" />
      </geometry>
    </collision>
  </link>
  <joint
    name="J11"
    type="continuous">
    <origin
      xyz="-0.015 0.05 -0.0074928"
      rpy="-3.1416 0 0.92013" />
    <parent
      link="Back_gripper" />
    <child
      link="Lower_frontlink" />
    <axis
      xyz="0 0 -1" />
  </joint>
</robot>